<?xml version="1.0" encoding="utf-8"?><testsuites name="pytest tests"><testsuite name="pytest" errors="9" failures="0" skipped="0" tests="9" time="0.755" timestamp="2025-08-01T10:41:36.555672-05:00" hostname="DESKTOP-B1UO3MR"><testcase classname="" name="test.artists" time="0.000"><error message="collection failure">..\..\..\..\AppData\Local\Programs\Python\Python313\Lib\importlib\__init__.py:88: in import_module
    return _bootstrap._gcd_import(name[level:], package, level)
           ^^^^^^^^^^^^^^^^^^^^^^^^^^^^^^^^^^^^^^^^^^^^^^^^^^^^
&lt;frozen importlib._bootstrap&gt;:1387: in _gcd_import
    ???
&lt;frozen importlib._bootstrap&gt;:1360: in _find_and_load
    ???
&lt;frozen importlib._bootstrap&gt;:1331: in _find_and_load_unlocked
    ???
&lt;frozen importlib._bootstrap&gt;:935: in _load_unlocked
    ???
..\..\..\..\AppData\Local\Programs\Python\Python313\Lib\site-packages\_pytest\assertion\rewrite.py:186: in exec_module
    exec(co, module.__dict__)
test\artists\conftest.py:6: in &lt;module&gt;
    from apps.artists.domain.entities import ArtistEntity
E   ModuleNotFoundError: No module named 'apps'</error></testcase><testcase classname="" name="test.genres" time="0.000"><error message="collection failure">..\..\..\..\AppData\Local\Programs\Python\Python313\Lib\importlib\__init__.py:88: in import_module
    return _bootstrap._gcd_import(name[level:], package, level)
           ^^^^^^^^^^^^^^^^^^^^^^^^^^^^^^^^^^^^^^^^^^^^^^^^^^^^
&lt;frozen importlib._bootstrap&gt;:1387: in _gcd_import
    ???
&lt;frozen importlib._bootstrap&gt;:1360: in _find_and_load
    ???
&lt;frozen importlib._bootstrap&gt;:1331: in _find_and_load_unlocked
    ???
&lt;frozen importlib._bootstrap&gt;:935: in _load_unlocked
    ???
..\..\..\..\AppData\Local\Programs\Python\Python313\Lib\site-packages\_pytest\assertion\rewrite.py:186: in exec_module
    exec(co, module.__dict__)
test\genres\conftest.py:5: in &lt;module&gt;
    import django
E   ModuleNotFoundError: No module named 'django'</error></testcase><testcase classname="" name="test.music_search.api.test_serializers" time="0.000"><error message="collection failure">import file mismatch:
imported module 'api.test_serializers' has this __file__ attribute:
  C:\Users\Marcwos\Documents\Ing Software\5to Semestre\streamflow_music_backend\test\albums\api\test_serializers.py
which is not the same as the test file we want to collect:
  C:\Users\Marcwos\Documents\Ing Software\5to Semestre\streamflow_music_backend\test\music_search\api\test_serializers.py
HINT: remove __pycache__ / .pyc files and/or use a unique basename for your test file modules</error></testcase><testcase classname="" name="test.music_search.domain.test_entities" time="0.000"><error message="collection failure">import file mismatch:
imported module 'domain.test_entities' has this __file__ attribute:
  C:\Users\Marcwos\Documents\Ing Software\5to Semestre\streamflow_music_backend\test\albums\domain\test_entities.py
which is not the same as the test file we want to collect:
  C:\Users\Marcwos\Documents\Ing Software\5to Semestre\streamflow_music_backend\test\music_search\domain\test_entities.py
HINT: remove __pycache__ / .pyc files and/or use a unique basename for your test file modules</error></testcase><testcase classname="" name="test.music_search.infrastructure.test_search_infrastructure" time="0.000"><error message="collection failure">ImportError while importing test module 'C:\Users\Marcwos\Documents\Ing Software\5to Semestre\streamflow_music_backend\test\music_search\infrastructure\test_search_infrastructure.py'.
Hint: make sure your test modules/packages have valid Python names.
Traceback:
..\..\..\..\AppData\Local\Programs\Python\Python313\Lib\importlib\__init__.py:88: in import_module
    return _bootstrap._gcd_import(name[level:], package, level)
           ^^^^^^^^^^^^^^^^^^^^^^^^^^^^^^^^^^^^^^^^^^^^^^^^^^^^
E   ModuleNotFoundError: No module named 'infrastructure.test_search_infrastructure'</error></testcase><testcase classname="" name="test.music_search.use_cases.test_search_use_cases" time="0.000"><error message="collection failure">ImportError while importing test module 'C:\Users\Marcwos\Documents\Ing Software\5to Semestre\streamflow_music_backend\test\music_search\use_cases\test_search_use_cases.py'.
Hint: make sure your test modules/packages have valid Python names.
Traceback:
..\..\..\..\AppData\Local\Programs\Python\Python313\Lib\importlib\__init__.py:88: in import_module
    return _bootstrap._gcd_import(name[level:], package, level)
           ^^^^^^^^^^^^^^^^^^^^^^^^^^^^^^^^^^^^^^^^^^^^^^^^^^^^
E   ModuleNotFoundError: No module named 'use_cases.test_search_use_cases'</error></testcase><testcase classname="" name="test.songs" time="0.000"><error message="collection failure">..\..\..\..\AppData\Local\Programs\Python\Python313\Lib\importlib\__init__.py:88: in import_module
    return _bootstrap._gcd_import(name[level:], package, level)
           ^^^^^^^^^^^^^^^^^^^^^^^^^^^^^^^^^^^^^^^^^^^^^^^^^^^^
&lt;frozen importlib._bootstrap&gt;:1387: in _gcd_import
    ???
&lt;frozen importlib._bootstrap&gt;:1360: in _find_and_load
    ???
&lt;frozen importlib._bootstrap&gt;:1331: in _find_and_load_unlocked
    ???
&lt;frozen importlib._bootstrap&gt;:935: in _load_unlocked
    ???
..\..\..\..\AppData\Local\Programs\Python\Python313\Lib\site-packages\_pytest\assertion\rewrite.py:186: in exec_module
    exec(co, module.__dict__)
test\songs\conftest.py:17: in &lt;module&gt;
    import django
E   ModuleNotFoundError: No module named 'django'</error></testcase><testcase classname="" name="test.user_profile" time="0.000"><error message="collection failure">..\..\..\..\AppData\Local\Programs\Python\Python313\Lib\importlib\__init__.py:88: in import_module
    return _bootstrap._gcd_import(name[level:], package, level)
           ^^^^^^^^^^^^^^^^^^^^^^^^^^^^^^^^^^^^^^^^^^^^^^^^^^^^
&lt;frozen importlib._bootstrap&gt;:1387: in _gcd_import
    ???
&lt;frozen importlib._bootstrap&gt;:1360: in _find_and_load
    ???
&lt;frozen importlib._bootstrap&gt;:1331: in _find_and_load_unlocked
    ???
&lt;frozen importlib._bootstrap&gt;:935: in _load_unlocked
    ???
..\..\..\..\AppData\Local\Programs\Python\Python313\Lib\site-packages\_pytest\assertion\rewrite.py:186: in exec_module
    exec(co, module.__dict__)
test\user_profile\conftest.py:15: in &lt;module&gt;
    import django
E   ModuleNotFoundError: No module named 'django'</error></testcase><testcase classname="pytest" name="internal" time="0.000"><error message="internal error">Traceback (most recent call last):
  File "C:\Users\Marcwos\AppData\Local\Programs\Python\Python313\Lib\site-packages\_pytest\main.py", line 289, in wrap_session
    session.exitstatus = doit(config, session) or 0
                         ~~~~^^^^^^^^^^^^^^^^^
  File "C:\Users\Marcwos\AppData\Local\Programs\Python\Python313\Lib\site-packages\_pytest\main.py", line 342, in _main
    config.hook.pytest_collection(session=session)
    ~~~~~~~~~~~~~~~~~~~~~~~~~~~~~^^^^^^^^^^^^^^^^^
  File "C:\Users\Marcwos\AppData\Local\Programs\Python\Python313\Lib\site-packages\pluggy\_hooks.py", line 512, in __call__
    return self._hookexec(self.name, self._hookimpls.copy(), kwargs, firstresult)
           ~~~~~~~~~~~~~~^^^^^^^^^^^^^^^^^^^^^^^^^^^^^^^^^^^^^^^^^^^^^^^^^^^^^^^^
  File "C:\Users\Marcwos\AppData\Local\Programs\Python\Python313\Lib\site-packages\pluggy\_manager.py", line 120, in _hookexec
    return self._inner_hookexec(hook_name, methods, kwargs, firstresult)
           ~~~~~~~~~~~~~~~~~~~~^^^^^^^^^^^^^^^^^^^^^^^^^^^^^^^^^^^^^^^^^
  File "C:\Users\Marcwos\AppData\Local\Programs\Python\Python313\Lib\site-packages\pluggy\_callers.py", line 167, in _multicall
    raise exception
  File "C:\Users\Marcwos\AppData\Local\Programs\Python\Python313\Lib\site-packages\pluggy\_callers.py", line 139, in _multicall
    teardown.throw(exception)
    ~~~~~~~~~~~~~~^^^^^^^^^^^
  File "C:\Users\Marcwos\AppData\Local\Programs\Python\Python313\Lib\site-packages\_pytest\logging.py", line 788, in pytest_collection
    return (yield)
            ^^^^^
  File "C:\Users\Marcwos\AppData\Local\Programs\Python\Python313\Lib\site-packages\pluggy\_callers.py", line 139, in _multicall
    teardown.throw(exception)
    ~~~~~~~~~~~~~~^^^^^^^^^^^
  File "C:\Users\Marcwos\AppData\Local\Programs\Python\Python313\Lib\site-packages\_pytest\warnings.py", line 99, in pytest_collection
    return (yield)
            ^^^^^
  File "C:\Users\Marcwos\AppData\Local\Programs\Python\Python313\Lib\site-packages\pluggy\_callers.py", line 139, in _multicall
    teardown.throw(exception)
    ~~~~~~~~~~~~~~^^^^^^^^^^^
  File "C:\Users\Marcwos\AppData\Local\Programs\Python\Python313\Lib\site-packages\_pytest\config\__init__.py", line 1450, in pytest_collection
    return (yield)
            ^^^^^
  File "C:\Users\Marcwos\AppData\Local\Programs\Python\Python313\Lib\site-packages\pluggy\_callers.py", line 121, in _multicall
    res = hook_impl.function(*args)
  File "C:\Users\Marcwos\AppData\Local\Programs\Python\Python313\Lib\site-packages\_pytest\main.py", line 353, in pytest_collection
    session.perform_collect()
    ~~~~~~~~~~~~~~~~~~~~~~~^^
  File "C:\Users\Marcwos\AppData\Local\Programs\Python\Python313\Lib\site-packages\_pytest\main.py", line 816, in perform_collect
    hook.pytest_collection_modifyitems(
    ~~~~~~~~~~~~~~~~~~~~~~~~~~~~~~~~~~^
        session=self, config=self.config, items=items
        ^^^^^^^^^^^^^^^^^^^^^^^^^^^^^^^^^^^^^^^^^^^^^
    )
    ^
  File "C:\Users\Marcwos\AppData\Local\Programs\Python\Python313\Lib\site-packages\pluggy\_hooks.py", line 512, in __call__
    return self._hookexec(self.name, self._hookimpls.copy(), kwargs, firstresult)
           ~~~~~~~~~~~~~~^^^^^^^^^^^^^^^^^^^^^^^^^^^^^^^^^^^^^^^^^^^^^^^^^^^^^^^^
  File "C:\Users\Marcwos\AppData\Local\Programs\Python\Python313\Lib\site-packages\pluggy\_manager.py", line 120, in _hookexec
    return self._inner_hookexec(hook_name, methods, kwargs, firstresult)
           ~~~~~~~~~~~~~~~~~~~~^^^^^^^^^^^^^^^^^^^^^^^^^^^^^^^^^^^^^^^^^
  File "C:\Users\Marcwos\AppData\Local\Programs\Python\Python313\Lib\site-packages\pluggy\_callers.py", line 167, in _multicall
    raise exception
  File "C:\Users\Marcwos\AppData\Local\Programs\Python\Python313\Lib\site-packages\pluggy\_callers.py", line 139, in _multicall
    teardown.throw(exception)
    ~~~~~~~~~~~~~~^^^^^^^^^^^
  File "C:\Users\Marcwos\AppData\Local\Programs\Python\Python313\Lib\site-packages\_pytest\cacheprovider.py", line 443, in pytest_collection_modifyitems
    res = yield
          ^^^^^
  File "C:\Users\Marcwos\AppData\Local\Programs\Python\Python313\Lib\site-packages\pluggy\_callers.py", line 139, in _multicall
    teardown.throw(exception)
    ~~~~~~~~~~~~~~^^^^^^^^^^^
  File "C:\Users\Marcwos\AppData\Local\Programs\Python\Python313\Lib\site-packages\_pytest\cacheprovider.py", line 373, in pytest_collection_modifyitems
    res = yield
          ^^^^^
  File "C:\Users\Marcwos\AppData\Local\Programs\Python\Python313\Lib\site-packages\pluggy\_callers.py", line 121, in _multicall
    res = hook_impl.function(*args)
  File "C:\Users\Marcwos\AppData\Local\Programs\Python\Python313\Lib\site-packages\pytest_django\plugin.py", line 442, in pytest_collection_modifyitems
    from django.test import TestCase, TransactionTestCase
ModuleNotFoundError: No module named 'django'</error></testcase></testsuite></testsuites>